Workbook

Sheet Executive Summary
A1: SummitBridge Health Plan
A2: Bending the Medical Cost Curve: A Precision Strategy for High-Cost Utilization, Avoidable Care & Retention
A4: THE BOTTOM LINE
A5: SummitBridge doesn't have a cost problem across the board — it has a concentration problem. In the 2024 book analyzed ($11.3M allowed, 800 members), 76% of spend is inpatient and just 40 members (top 5%) drive 20% of every dollar. The winning move is precision, not broad cuts: wrap the few members who matter, divert the care that shouldn't be in the ED, and stop losing our most expensive members to cost confusion. We identify ~$653K of Year-1 addressable savings (~5.8% of allowed) with a credible path to far more in inpatient/readmission management — all without touching quality.
A7: # | B7: Strategic storyline | C7: What the data shows | D7: Our proposition (action) | E7: Year-1 impact | F7: Owner · horizon
A8: 1 | B8: Build a High-Cost Claimant Command Center | C8: 40 members (top 5%) drive 20.5% of allowed spend, running $5,280 PMPM vs $1,150 for the rest. Their cost is concentrated in inpatient (76% of the book) and oncology/specialty biologics. ▸ National benchmark: the top 5% of Americans drive ~50% of all U.S. health spending (AHRQ MEPS) — concentration is structural, so a focused pod is the highest-ROI lever. | D8: Stand up a concierge care-management pod that owns these 40 members: proactive outreach, site-of-care steering, prior-auth refinement, and readmission prevention. Precision beats population-wide programs. | E8: ="≈ $"&TEXT('Member Spend'!$U$5*0.1,"#,##0")&"/yr from a 10% cut on their $2.3M — more impact than any broad program, from 40 relationships" -> ≈ $231,730/yr from a 10% cut on their $2.3M — more impact than any broad program, from 40 relationships | F8: Care Management · 0–6 mo
A9: 2 | B9: Divert the 3-in-4 ED Visits That Don't Belong There | C9: 914 of 1,209 ED visits (76%) are avoidable or potentially avoidable. The average ED visit costs $1,127 vs $135 in urgent care — an ~8x setting premium. 65+ members and Kentucky are the hotspots. ▸ National benchmark: 155M U.S. ED visits in 2022; ~10% are non-urgent and use skews to age 75+ (CDC NCHS) — our 65+ hotspot mirrors the national pattern. | D9: Launch an ED diversion program: 24/7 nurse triage line, telehealth-first routing, urgent-care steering, and embedded navigators for the 65+/KY hotspots. | E9: ="≈ $"&TEXT('Category Spend'!$B$42,"#,##0")&"/yr diverting just 20% to urgent care; scales with adoption" -> ≈ $181,354/yr diverting just 20% to urgent care; scales with adoption | F9: Population Health · 0–9 mo
A10: 3 | B10: Shift Specialty Pharmacy to Lower-Cost Sites | C10: Specialty Rx is $791K of allowed; oncology biologics alone are 43% of it. These are frequently infused in the highest-cost hospital outpatient setting. ▸ National benchmark: U.S. retail Rx hit $467B in 2024 (+7.9%), the fastest-growing spend category, led by GLP-1/diabetes-obesity drugs (CMS NHE) — the cost curve is steepening. | D10: Refine prior-auth and formulary; steer eligible infusions to home/office and biosimilars. The model quantifies 5/10/15% reductions at $40K/$79K/$119K. | E10: ="Up to $"&TEXT('Category Spend'!$D$31,"#,##0")&"/yr at a 15% specialty Rx reduction; low clinical risk" -> Up to $118,685/yr at a 15% specialty Rx reduction; low clinical risk | F10: Pharmacy · 3–12 mo
A11: 4 | B11: Treat Behavioral Health to Break the ED Cycle | C11: BH isn't cheap because of price ($175/visit, ~PCP level) — it's under-treated: 45% of members touch BH but average only 1.3 visits/yr. BH members average 48% more ED visits (1.83 vs 1.24) with identical inpatient use. ▸ National benchmark: national ED use concentrates in older, complex patients and BH is a recognized ED-diversion lever (CDC; see External Benchmarks tab). | D11: Embed collaborative-care / measurement-based BH with telehealth access and PCP integration to sustain treatment and cut downstream ED use. | E11: ="≈ $"&TEXT(('Behavioral Health'!$B$20*('Behavioral Health'!$B$21-'Behavioral Health'!$C$21))*0.5*'Category Spend'!$E$4,"#,##0")&"/yr in avoided ED if half the excess BH-member ED is prevented" -> ≈ $121,101/yr in avoided ED if half the excess BH-member ED is prevented | F11: Population Health · 6–12 mo
A12: 5 | B12: Retention = Margin: Stop Losing Our Costliest Members | C12: 11.6% disenrolled. Leavers ran 36% higher PMPM ($1,770 vs $1,302) at similar risk — cost exposure, not sickness, drives exits. Premium Affordability + Network/Access account for 71% of stated reasons. ▸ National benchmark: CMS projects ~4.7M Marketplace enrollees will exit when enhanced subsidies expire in 2026 — affordability pressure is systemic, not just ours. | D12: Deploy cost-transparency tools and an in-network care finder; proactively outreach high-PMPM members flagged for affordability; close rural network-adequacy gaps. | E12: Protects renewal revenue on 93 exits and curbs adverse-selection drift; each retained commercial group compounds | F12: Member Experience · 0–6 mo
A14: PRIORITIZED SAVINGS ROADMAP
B15: Initiative | C15: Horizon | D15: Type | E15: Year-1 $
B16: High-cost claimant pod (10% of top-5% spend) | C16: 0–6 mo | D16: Quick win | E16: ='Member Spend'!$U$5*0.1 -> 231730.37
B17: ED diversion to urgent care (20% of avoidable) | C17: 0–9 mo | D17: Quick win | E17: ='Category Spend'!$B$42 -> 181353.58
B18: Specialty Rx site-of-care / biosimilar (15%) | C18: 3–12 mo | D18: Quick win | E18: ='Category Spend'!$D$31 -> 118685.01
B19: BH engagement → downstream ED avoidance | C19: 6–12 mo | D19: Strategic | E19: =('Behavioral Health'!$B$20*('Behavioral Health'!$B$21-'Behavioral Health'!$C$21))*0.5*'Category Spend'!$E$4 -> 121100.91
B20: TOTAL Year-1 addressable savings | E20: =SUM(E16:E19) -> 652869.86
B21: % of total allowed spend | E21: =E20/'Member Spend'!$U$6 -> 0.057667639
B22: ▶ Strategic prize (Phase 2): Inpatient is 76% of allowed ($8.6M). A readmission-reduction + discharge-planning + SNF-at-home program here can exceed all quick wins combined — the biggest curve-bender, flagged for Phase 2.
A24: NOTEWORTHY PROPOSITIONS (the differentiators)
B25: ▪ The 40-Member P&L — A small concierge pod managing 40 members can bend more cost (~$232K) than any plan-wide program. Concentrate resources where the dollars actually are.
B26: ▪ Make triage the front door — An 8x cost gap between the ED ($1,127) and urgent care ($135) means every appropriately diverted visit is near-pure margin.
B27: ▪ Behavioral health is a medical-cost lever, not a carve-out — BH members use 48% more ED. Funding sustained BH treatment is cost avoidance, not just a benefit expense.
B28: ▪ Retention is underwriting — We're shedding members at 36% higher PMPM but similar risk. That is adverse retention; cost-transparency tools are a medical-cost instrument.
B29: ▪ Data as an operating system — A monthly claims + enrollment + provider integration (this workbook) moves utilization management and pricing from retrospective to prospective.
B30: ▪ Quality-neutral by design — None of the ~$653K requires denying care; it is site-of-care, engagement, and steering. Leadership can approve without clinical risk.
A32: WHY THIS WINS
B33: The recommendation is evidence-based (every number traces to the model), quantified (~$653K Year-1, ~5.8% of allowed, with a larger inpatient prize in Phase 2), quality-neutral, prioritized (quick wins vs. strategic), and operationalized — a live dashboard with KPI definitions, refresh cadence, and named owners. It answers all four case tasks and gives leadership a plan they can fund on Monday.
A35: APPENDIX: METHODOLOGY & ASSUMPTIONS
A36: Data & scope | B36: 2024 analytic sample: 800 members · 8,462 member-months · 5,961 claim lines · $11.3M allowed. Primary cost metric = allowed_amount. This is a sample, not the full ~$2.1B / 420K-life book — rates are directional, mix and concentration patterns are the takeaway.
A37: Definitions | B37: PMPM = allowed ÷ member-months. ED/1,000 = (ED claims ÷ member-months) × 1,000. High-cost = top 5% of members by allowed (≥ 95th-pct cutoff, 40 members). Avoidable ED = claims whose primary ICD-10 maps to 'Avoidable'/'Potentially Avoidable' in the reference table. OON = in_network_flag = 'N'.
A38: Joins | B38: claims↔enrollment (member_id): demographics, state, attributed PCP. claims↔avoidable_ed_reference (diagnosis_code_1): ED avoidability. enrollment↔providers (attributed_pcp_npi): PCP quality. spend↔member_months (member_id / calendar_month): exposure & PMPM. All via XLOOKUP/SUMIFS — auditable in helper cols AA:AG on 'claims'.
A39: Savings model | B39: High-cost pod: 10% reduction on top-5% allowed ($2.32M). ED diversion: 20% of avoidable+potentially-avoidable ED visits shifted to urgent care, valued at (avg ED $1,127 − avg UC $135)/visit. Specialty Rx: 5/10/15% reduction on $791K. BH→ED: 50% of excess ED among BH members (1.83 vs 1.24 visits) × avg ED cost. Figures are gross, quality-neutral (site-of-care/engagement, no care denials), pre-implementation cost.
A40: Caveats | B40: Monthly trend charts use Mar–Dec (full 800-member exposure); Jan–Feb excluded (enrollment ramp). OON (55 lines) and some age/state cells are small-sample — treat as directional. 7-day post-ED PCP follow-up and 30-day readmission require visit-sequencing/admission linkage not in this extract — defined as prospective KPIs. Retention impact is framed as protected premium (no premium field to quantify directly).

Sheet External Benchmarks
A1: External Benchmarks — Official & Government Sources
A2: SummitBridge findings validated against national data (AHRQ, CDC/NCHS, CMS, MedPAC). Every benchmark cell carries its source + URL as a comment.
A4: # | B4: Theme | C4: SummitBridge (our data) | D4: National benchmark (official) | E4: Source | F4: Implication / proposition
A5: 1 | B5: High-cost concentration | C5: Top 5% of members = 20.5% of allowed spend; $5,280 vs $1,150 PMPM. | D5: Nationally, the top 5% of people account for ~50% of all U.S. health spending (50.8% in 2015); the bottom 50% just 2.8%. | E5: AHRQ MEPS Stat Brief #506 / #521 | F5: Concentration is structural, not anomalous. A high-cost claimant care pod is the highest-ROI lever — our 20.5% understates the ceiling because our book excludes the uninsured/institutionalized.
A6: 2 | B6: Avoidable ED use | C6: 76% of ED visits avoidable/potentially avoidable; ED $1,127 vs urgent care $135 (8x). | D6: 155 million U.S. ED visits in 2022; ~10% triaged non-urgent; highest visit rate among adults 75+ (76 per 100). | E6: CDC NCHS Data Brief #503 (2024) | F6: ED overuse and an elderly skew are national patterns — our 65+ hotspot mirrors the data. Triage lines + urgent-care/telehealth routing are proven diversion levers.
A7: 3 | B7: Specialty pharmacy trend | C7: Specialty Rx $791K; oncology biologics 43%; GLP-1 a top class. | D7: U.S. retail Rx spending reached $467.0B in 2024 (+7.9%); projected fastest-growing NHE category (5.7%/yr, 2025-34); diabetes/obesity (GLP-1) drugs a key driver. | E7: CMS NHE 2024 Highlights | F7: Specialty/GLP-1 is the steepest national cost curve. PA refinement, biosimilar & site-of-care shifts protect SummitBridge against a trend that is accelerating faster than any other category.
A8: 4 | B8: Inpatient & readmissions | C8: Inpatient = 76% of our allowed spend ($8.6M); the single largest bucket. | D8: ~1 in 5 Medicare patients are readmitted within 30 days; MedPAC estimated ~75% of 30-day readmissions are potentially preventable (~$12B in Medicare spend). | E8: MedPAC (2007 Report to Congress) | F8: The Phase-2 prize. Inpatient dwarfs every quick win; national evidence says most 30-day readmissions are preventable. Discharge planning + transitional care target the largest, most-addressable bucket.
A9: 5 | B9: Retention & affordability | C9: 11.6% disenrollment; leavers 36% higher PMPM; 'Premium Affordability' the #1 exit reason. | D9: CMS projects ~4.7M direct-purchase (Marketplace) enrollees will drop when enhanced subsidies expire in 2026; insured share falls from 91.8% (2024) toward 90.5% (2034). | E9: CMS NHE Projections 2024-33 | F9: Affordability pressure is systemic and about to intensify. Cost-transparency tools + proactive retention outreach to high-PMPM members protect the book precisely as subsidy-driven affordability shocks hit.
A11: BOTTOM LINE: Every SummitBridge storyline is directionally consistent with national government data — our recommendations aren't outliers, they target the same cost drivers CMS, AHRQ, CDC and MedPAC flag nationally.

Sheet README
A1: SummitBridge Health Plan — Medical Cost & Utilization Analysis
A2: Analysis period: Jan 1 – Dec 31, 2024 | Cost metric: allowed_amount | Prepared by: Healthcare Analytics
A4: 1. DATA SOURCES
A5: Sheet | B5: Grain | C5: Rows | D5: Key fields
A6: claims | B6: 1 claim line | C6: =COUNTA(claims!A2:A100000) -> 5961 | D6: member_id, rendering_npi, service dates, service_category, allowed_amount, in_network_flag, diagnosis_code_1
A7: enrollment | B7: 1 member | C7: =COUNTA(enrollment!A2:A100000) -> 800 | D7: member_id, lob, state, county, age, gender, risk_score, attributed_pcp_npi, disenrollment_reason
A8: member_months | B8: 1 member-month | C8: =COUNTA(member_months!A2:A100000) -> 8462 | D8: member_id, lob, state, calendar_month, member_months (exposure)
A9: providers | B9: 1 provider | C9: =COUNTA(providers!A2:A100000) -> 10 | D9: npi, provider_type, specialty_desc, network_status, quality_score, panel_size, state
A10: avoidable_ed_reference | B10: 1 ICD-10 code | C10: =COUNTA(avoidable_ed_reference!A2:A100000) -> 12 | D10: icd10_code, description, avoidable_category (Avoidable / Potentially Avoidable / Non-Avoidable)
A12: 2. JOINS
A13: claims.member_id → enrollment.member_id | B13: adds member demographics, state, attributed PCP to each claim (helper cols AB-AE)
A14: claims.diagnosis_code_1 → avoidable_ed_reference.icd10_code | B14: classifies ED visits as Avoidable / Potentially Avoidable / Non-Avoidable (helper col AA)
A15: enrollment.attributed_pcp_npi → providers.npi | B15: adds PCP quality_score & network_status (helper col AF; Member Spend tab)
A16: claims.member_id / member_months.member_id | B16: aligns spend to exposure for PMPM (SUMIFS on member-level)
A18: 3. FILTERS & SCOPE
A19: • All 5,961 claim lines fall within 2024 service dates (serial 45292–45656); no period filter needed.
A20: • avoidable_category applies to ED visits only in downstream analysis; other categories retain the label but are not acted on.
A21: • ED avoidable-shift savings model uses Avoidable + Potentially Avoidable ED visits as the divertible pool.
A22: • OON defined as in_network_flag = 'N'. Only 55 of 5,961 lines are OON in this dataset.
A23: • Member months are pre-calculated (1 row = 1 member-month); total exposure = 8,462.
A25: 4. ASSUMPTIONS & KPI DEFINITIONS
A26: Metric | B26: Definition
A27: Primary cost metric | B27: allowed_amount (health-plan liability + member cost share), per assumptions.
A28: PMPM | B28: Total Allowed Amount ÷ Member Months.
A29: ED visits per 1,000 | B29: (ED claims ÷ Member Months) × 1,000.
A30: High-cost member | B30: Member in the top 5% of total allowed spend in the period (allowed ≥ 95th percentile). 800 members → ~40 members.
A31: IP utilization / 1,000 | B31: (Inpatient claim lines ÷ Member Months) × 1,000.
A32: OON rate | B32: Out-of-network allowed ÷ total allowed (also shown as % of claim lines).
A34: 5. HELPER COLUMNS ADDED TO 'claims' (AA:AF)
A35: AA avoidable_category · AB member_state · AC member_age · AD age_band · AE attributed_pcp_npi · AF pcp_quality_score — all XLOOKUP-based, auditable in the formula bar.
A37: 6. TAB INDEX
A38: Member Spend · Category Spend (+ savings scenarios) · Avoidable ED · Behavioral Health · OON & Retention · Dashboard (final)

Sheet Member Spend
A1: member_id | B1: lob | C1: state | D1: county | E1: age | F1: age_band | G1: gender | H1: risk_score | I1: attributed_pcp_npi | J1: pcp_quality_score | K1: member_months | L1: total_allowed | M1: PMPM | N1: inpatient_allowed | O1: ED_allowed | P1: specialtyRx_allowed | Q1: high_cost_flag | S1: HIGH-COST CONCENTRATION (top 5%) | AA1: bh_claims | AB1: ed_visits | AC1: ip_visits | AD1: bh_flag | AE1: disenroll_reason | AF1: disenroll_flag
A2: =enrollment!A2 -> M-000001 | B2: =enrollment!F2 -> Commercial | C2: =enrollment!I2 -> KY | D2: =enrollment!J2 -> Jefferson | E2: =enrollment!L2 -> 53 | F2: {=_xlfn.IFS(E2<18,"0-17",E2<35,"18-34",E2<50,"35-49",E2<65,"50-64",TRUE,"65+")} -> 50-64 | G2: =enrollment!M2 -> F | H2: =enrollment!N2 -> 0.82 | I2: =enrollment!O2 -> 9012345678 | J2: =IFERROR(_xlfn.XLOOKUP(I2,providers!$B$2:$B$11,providers!$Q$2:$Q$11),"") -> 4.3 | K2: =SUMIFS(member_months!$F:$F,member_months!$A:$A,$A2) -> 11 | L2: =SUMIFS(claims!$Q:$Q,claims!$B:$B,$A2) -> 484.53 | M2: =IF(K2=0,0,L2/K2) -> 44.048182 | N2: =SUMIFS(claims!$Q:$Q,claims!$B:$B,$A2,claims!$Z:$Z,"Inpatient") -> 0 | O2: =SUMIFS(claims!$Q:$Q,claims!$B:$B,$A2,claims!$Z:$Z,"ED") -> 0 | P2: =SUMIFS(claims!$Q:$Q,claims!$B:$B,$A2,claims!$Z:$Z,"Specialty Rx") -> 0 | Q2: =IF($L2>=$U$2,1,0) -> 0 | S2: High-cost threshold (40th highest allowed) | U2: =LARGE($L$2:$L$801,40) -> 43489.4 | AA2: =COUNTIFS(claims!$B:$B,$A2,claims!$Z:$Z,"Behavioral Health") -> 1 | AB2: =COUNTIFS(claims!$B:$B,$A2,claims!$Z:$Z,"ED") -> 0 | AC2: =COUNTIFS(claims!$B:$B,$A2,claims!$Z:$Z,"Inpatient") -> 0 | AD2: =IF(AA2>0,1,0) -> 1 | AE2: =IF(enrollment!P2="","",enrollment!P2) | AF2: =IF(enrollment!P2="",0,1) -> 0
A3: =enrollment!A3 -> M-000002 | B3: =enrollment!F3 -> Marketplace | C3: =enrollment!I3 -> KY | D3: =enrollment!J3 -> Jefferson | E3: =enrollment!L3 -> 36 | F3: {=_xlfn.IFS(E3<18,"0-17",E3<35,"18-34",E3<50,"35-49",E3<65,"50-64",TRUE,"65+")} -> 35-49 | G3: =enrollment!M3 -> M | H3: =enrollment!N3 -> 0.88 | I3: =enrollment!O3 -> 9012345678 | J3: =IFERROR(_xlfn.XLOOKUP(I3,providers!$B$2:$B$11,providers!$Q$2:$Q$11),"") -> 4.3 | K3: =SUMIFS(member_months!$F:$F,member_months!$A:$A,$A3) -> 10 | L3: =SUMIFS(claims!$Q:$Q,claims!$B:$B,$A3) -> 2712.06 | M3: =IF(K3=0,0,L3/K3) -> 271.206 | N3: =SUMIFS(claims!$Q:$Q,claims!$B:$B,$A3,claims!$Z:$Z,"Inpatient") -> 0 | O3: =SUMIFS(claims!$Q:$Q,claims!$B:$B,$A3,claims!$Z:$Z,"ED") -> 2394.88 | P3: =SUMIFS(claims!$Q:$Q,claims!$B:$B,$A3,claims!$Z:$Z,"Specialty Rx") -> 0 | Q3: =IF($L3>=$U$2,1,0) -> 0 | S3: # high-cost members | U3: =SUM($Q$2:$Q$801) -> 40 | AA3: =COUNTIFS(claims!$B:$B,$A3,claims!$Z:$Z,"Behavioral Health") -> 0 | AB3: =COUNTIFS(claims!$B:$B,$A3,claims!$Z:$Z,"ED") -> 2 | AC3: =COUNTIFS(claims!$B:$B,$A3,claims!$Z:$Z,"Inpatient") -> 0 | AD3: =IF(AA3>0,1,0) -> 0 | AE3: =IF(enrollment!P3="","",enrollment!P3) | AF3: =IF(enrollment!P3="",0,1) -> 0
A4: =enrollment!A4 -> M-000003 | B4: =enrollment!F4 -> Marketplace | C4: =enrollment!I4 -> GA | D4: =enrollment!J4 -> Fulton | E4: =enrollment!L4 -> 24 | F4: {=_xlfn.IFS(E4<18,"0-17",E4<35,"18-34",E4<50,"35-49",E4<65,"50-64",TRUE,"65+")} -> 18-34 | G4: =enrollment!M4 -> M | H4: =enrollment!N4 -> 1.27 | I4: =enrollment!O4 -> 8901234567 | J4: =IFERROR(_xlfn.XLOOKUP(I4,providers!$B$2:$B$11,providers!$Q$2:$Q$11),"") -> 3.7 | K4: =SUMIFS(member_months!$F:$F,member_months!$A:$A,$A4) -> 6 | L4: =SUMIFS(claims!$Q:$Q,claims!$B:$B,$A4) -> 23008.12 | M4: =IF(K4=0,0,L4/K4) -> 3834.6867 | N4: =SUMIFS(claims!$Q:$Q,claims!$B:$B,$A4,claims!$Z:$Z,"Inpatient") -> 17493.55 | O4: =SUMIFS(claims!$Q:$Q,claims!$B:$B,$A4,claims!$Z:$Z,"ED") -> 3570.21 | P4: =SUMIFS(claims!$Q:$Q,claims!$B:$B,$A4,claims!$Z:$Z,"Specialty Rx") -> 1192.21 | Q4: =IF($L4>=$U$2,1,0) -> 0 | S4: % of members | U4: =U3/COUNTA($A$2:$A$801) -> 0.05 | AA4: =COUNTIFS(claims!$B:$B,$A4,claims!$Z:$Z,"Behavioral Health") -> 0 | AB4: =COUNTIFS(claims!$B:$B,$A4,claims!$Z:$Z,"ED") -> 3 | AC4: =COUNTIFS(claims!$B:$B,$A4,claims!$Z:$Z,"Inpatient") -> 1 | AD4: =IF(AA4>0,1,0) -> 0 | AE4: =IF(enrollment!P4="","",enrollment!P4) -> Premium Affordability | AF4: =IF(enrollment!P4="",0,1) -> 1
A5: =enrollment!A5 -> M-000004 | B5: =enrollment!F5 -> Marketplace | C5: =enrollment!I5 -> TN | D5: =enrollment!J5 -> Davidson | E5: =enrollment!L5 -> 71 | F5: {=_xlfn.IFS(E5<18,"0-17",E5<35,"18-34",E5<50,"35-49",E5<65,"50-64",TRUE,"65+")} -> 65+ | G5: =enrollment!M5 -> M | H5: =enrollment!N5 -> 2.08 | I5: =enrollment!O5 -> 5678901234 | J5: =IFERROR(_xlfn.XLOOKUP(I5,providers!$B$2:$B$11,providers!$Q$2:$Q$11),"") -> 3.8 | K5: =SUMIFS(member_months!$F:$F,member_months!$A:$A,$A5) -> 12 | L5: =SUMIFS(claims!$Q:$Q,claims!$B:$B,$A5) -> 17525.56 | M5: =IF(K5=0,0,L5/K5) -> 1460.4633 | N5: =SUMIFS(claims!$Q:$Q,claims!$B:$B,$A5,claims!$Z:$Z,"Inpatient") -> 14200.28 | O5: =SUMIFS(claims!$Q:$Q,claims!$B:$B,$A5,claims!$Z:$Z,"ED") -> 1999.87 | P5: =SUMIFS(claims!$Q:$Q,claims!$B:$B,$A5,claims!$Z:$Z,"Specialty Rx") -> 721.52 | Q5: =IF($L5>=$U$2,1,0) -> 0 | S5: High-cost total allowed | U5: =SUMIFS($L$2:$L$801,$Q$2:$Q$801,1) -> 2317303.7 | AA5: =COUNTIFS(claims!$B:$B,$A5,claims!$Z:$Z,"Behavioral Health") -> 1 | AB5: =COUNTIFS(claims!$B:$B,$A5,claims!$Z:$Z,"ED") -> 2 | AC5: =COUNTIFS(claims!$B:$B,$A5,claims!$Z:$Z,"Inpatient") -> 1 | AD5: =IF(AA5>0,1,0) -> 1 | AE5: =IF(enrollment!P5="","",enrollment!P5) | AF5: =IF(enrollment!P5="",0,1) -> 0
A6: =enrollment!A6 -> M-000005 | B6: =enrollment!F6 -> Marketplace | C6: =enrollment!I6 -> TN | D6: =enrollment!J6 -> Rural-Cannon | E6: =enrollment!L6 -> 53 | F6: {=_xlfn.IFS(E6<18,"0-17",E6<35,"18-34",E6<50,"35-49",E6<65,"50-64",TRUE,"65+")} -> 50-64 | G6: =enrollment!M6 -> F | H6: =enrollment!N6 -> 1.03 | I6: =enrollment!O6 -> 0 | J6: =IFERROR(_xlfn.XLOOKUP(I6,providers!$B$2:$B$11,providers!$Q$2:$Q$11),"") | K6: =SUMIFS(member_months!$F:$F,member_months!$A:$A,$A6) -> 6 | L6: =SUMIFS(claims!$Q:$Q,claims!$B:$B,$A6) -> 3356.94 | M6: =IF(K6=0,0,L6/K6) -> 559.49 | N6: =SUMIFS(claims!$Q:$Q,claims!$B:$B,$A6,claims!$Z:$Z,"Inpatient") -> 0 | O6: =SUMIFS(claims!$Q:$Q,claims!$B:$B,$A6,claims!$Z:$Z,"ED") -> 2569.05 | P6: =SUMIFS(claims!$Q:$Q,claims!$B:$B,$A6,claims!$Z:$Z,"Specialty Rx") -> 0 | Q6: =IF($L6>=$U$2,1,0) -> 0 | S6: Total allowed (all members) | U6: =SUM($L$2:$L$801) -> 11321252 | AA6: =COUNTIFS(claims!$B:$B,$A6,claims!$Z:$Z,"Behavioral Health") -> 1 | AB6: =COUNTIFS(claims!$B:$B,$A6,claims!$Z:$Z,"ED") -> 2 | AC6: =COUNTIFS(claims!$B:$B,$A6,claims!$Z:$Z,"Inpatient") -> 0 | AD6: =IF(AA6>0,1,0) -> 1 | AE6: =IF(enrollment!P6="","",enrollment!P6) -> Network Adequacy | AF6: =IF(enrollment!P6="",0,1) -> 1
A7: =enrollment!A7 -> M-000006 | B7: =enrollment!F7 -> Commercial | C7: =enrollment!I7 -> KY | D7: =enrollment!J7 -> Hardin | E7: =enrollment!L7 -> 54 | F7: {=_xlfn.IFS(E7<18,"0-17",E7<35,"18-34",E7<50,"35-49",E7<65,"50-64",TRUE,"65+")} -> 50-64 | G7: =enrollment!M7 -> M | H7: =enrollment!N7 -> 1.26 | I7: =enrollment!O7 -> 9012345678 | J7: =IFERROR(_xlfn.XLOOKUP(I7,providers!$B$2:$B$11,providers!$Q$2:$Q$11),"") -> 4.3 | K7: =SUMIFS(member_months!$F:$F,member_months!$A:$A,$A7) -> 10 | L7: =SUMIFS(claims!$Q:$Q,claims!$B:$B,$A7) -> 21092.86 | M7: =IF(K7=0,0,L7/K7) -> 2109.286 | N7: =SUMIFS(claims!$Q:$Q,claims!$B:$B,$A7,claims!$Z:$Z,"Inpatient") -> 20651.94 | O7: =SUMIFS(claims!$Q:$Q,claims!$B:$B,$A7,claims!$Z:$Z,"ED") -> 0 | P7: =SUMIFS(claims!$Q:$Q,claims!$B:$B,$A7,claims!$Z:$Z,"Specialty Rx") -> 0 | Q7: =IF($L7>=$U$2,1,0) -> 0 | S7: High-cost share of allowed | U7: =U5/U6 -> 0.20468617 | AA7: =COUNTIFS(claims!$B:$B,$A7,claims!$Z:$Z,"Behavioral Health") -> 0 | AB7: =COUNTIFS(claims!$B:$B,$A7,claims!$Z:$Z,"ED") -> 0 | AC7: =COUNTIFS(claims!$B:$B,$A7,claims!$Z:$Z,"Inpatient") -> 1 | AD7: =IF(AA7>0,1,0) -> 0 | AE7: =IF(enrollment!P7="","",enrollment!P7) | AF7: =IF(enrollment!P7="",0,1) -> 0
A8: =enrollment!A8 -> M-000007 | B8: =enrollment!F8 -> Commercial | C8: =enrollment!I8 -> TN | D8: =enrollment!J8 -> Davidson | E8: =enrollment!L8 -> 69 | F8: {=_xlfn.IFS(E8<18,"0-17",E8<35,"18-34",E8<50,"35-49",E8<65,"50-64",TRUE,"65+")} -> 65+ | G8: =enrollment!M8 -> F | H8: =enrollment!N8 -> 2.21 | I8: =enrollment!O8 -> 5678901234 | J8: =IFERROR(_xlfn.XLOOKUP(I8,providers!$B$2:$B$11,providers!$Q$2:$Q$11),"") -> 3.8 | K8: =SUMIFS(member_months!$F:$F,member_months!$A:$A,$A8) -> 10 | L8: =SUMIFS(claims!$Q:$Q,claims!$B:$B,$A8) -> 2461.01 | M8: =IF(K8=0,0,L8/K8) -> 246.101 | N8: =SUMIFS(claims!$Q:$Q,claims!$B:$B,$A8,claims!$Z:$Z,"Inpatient") -> 0 | O8: =SUMIFS(claims!$Q:$Q,claims!$B:$B,$A8,claims!$Z:$Z,"ED") -> 1186.92 | P8: =SUMIFS(claims!$Q:$Q,claims!$B:$B,$A8,claims!$Z:$Z,"Specialty Rx") -> 820.55 | Q8: =IF($L8>=$U$2,1,0) -> 0 | S8: Avg PMPM – high-cost | U8: =AVERAGEIFS($M$2:$M$801,$Q$2:$Q$801,1) -> 5280.3967 | AA8: =COUNTIFS(claims!$B:$B,$A8,claims!$Z:$Z,"Behavioral Health") -> 0 | AB8: =COUNTIFS(claims!$B:$B,$A8,claims!$Z:$Z,"ED") -> 1 | AC8: =COUNTIFS(claims!$B:$B,$A8,claims!$Z:$Z,"Inpatient") -> 0 | AD8: =IF(AA8>0,1,0) -> 0 | AE8: =IF(enrollment!P8="","",enrollment!P8) | AF8: =IF(enrollment!P8="",0,1) -> 0
A9: =enrollment!A9 -> M-000008 | B9: =enrollment!F9 -> Marketplace | C9: =enrollment!I9 -> OH | D9: =enrollment!J9 -> Franklin | E9: =enrollment!L9 -> 30 | F9: {=_xlfn.IFS(E9<18,"0-17",E9<35,"18-34",E9<50,"35-49",E9<65,"50-64",TRUE,"65+")} -> 18-34 | G9: =enrollment!M9 -> M | H9: =enrollment!N9 -> 0.73 | I9: =enrollment!O9 -> 6789012345 | J9: =IFERROR(_xlfn.XLOOKUP(I9,providers!$B$2:$B$11,providers!$Q$2:$Q$11),"") -> 4.1 | K9: =SUMIFS(member_months!$F:$F,member_months!$A:$A,$A9) -> 12 | L9: =SUMIFS(claims!$Q:$Q,claims!$B:$B,$A9) -> 761.05 | M9: =IF(K9=0,0,L9/K9) -> 63.420833 | N9: =SUMIFS(claims!$Q:$Q,claims!$B:$B,$A9,claims!$Z:$Z,"Inpatient") -> 0 | O9: =SUMIFS(claims!$Q:$Q,claims!$B:$B,$A9,claims!$Z:$Z,"ED") -> 0 | P9: =SUMIFS(claims!$Q:$Q,claims!$B:$B,$A9,claims!$Z:$Z,"Specialty Rx") -> 0 | Q9: =IF($L9>=$U$2,1,0) -> 0 | S9: Avg PMPM – all other members | U9: =AVERAGEIFS($M$2:$M$801,$Q$2:$Q$801,0) -> 1149.9835 | AA9: =COUNTIFS(claims!$B:$B,$A9,claims!$Z:$Z,"Behavioral Health") -> 0 | AB9: =COUNTIFS(claims!$B:$B,$A9,claims!$Z:$Z,"ED") -> 0 | AC9: =COUNTIFS(claims!$B:$B,$A9,claims!$Z:$Z,"Inpatient") -> 0 | AD9: =IF(AA9>0,1,0) -> 0 | AE9: =IF(enrollment!P9="","",enrollment!P9) | AF9: =IF(enrollment!P9="",0,1) -> 0
A10: =enrollment!A10 -> M-000009 | B10: =enrollment!F10 -> Marketplace | C10: =enrollment!I10 -> GA | D10: =enrollment!J10 -> Cherokee | E10: =enrollment!L10 -> 35 | F10: {=_xlfn.IFS(E10<18,"0-17",E10<35,"18-34",E10<50,"35-49",E10<65,"50-64",TRUE,"65+")} -> 35-49 | G10: =enrollment!M10 -> F | H10: =enrollment!N10 -> 0.71 | I10: =enrollment!O10 -> 8901234567 | J10: =IFERROR(_xlfn.XLOOKUP(I10,providers!$B$2:$B$11,providers!$Q$2:$Q$11),"") -> 3.7 | K10: =SUMIFS(member_months!$F:$F,member_months!$A:$A,$A10) -> 11 | L10: =SUMIFS(claims!$Q:$Q,claims!$B:$B,$A10) -> 3030.2 | M10: =IF(K10=0,0,L10/K10) -> 275.47273 | N10: =SUMIFS(claims!$Q:$Q,claims!$B:$B,$A10,claims!$Z:$Z,"Inpatient") -> 0 | O10: =SUMIFS(claims!$Q:$Q,claims!$B:$B,$A10,claims!$Z:$Z,"ED") -> 1326.41 | P10: =SUMIFS(claims!$Q:$Q,claims!$B:$B,$A10,claims!$Z:$Z,"Specialty Rx") -> 1088.66 | Q10: =IF($L10>=$U$2,1,0) -> 0 | S10: Total member months | U10: =SUM($K$2:$K$801) -> 8462 | AA10: =COUNTIFS(claims!$B:$B,$A10,claims!$Z:$Z,"Behavioral Health") -> 0 | AB10: =COUNTIFS(claims!$B:$B,$A10,claims!$Z:$Z,"ED") -> 1 | AC10: =COUNTIFS(claims!$B:$B,$A10,claims!$Z:$Z,"Inpatient") -> 0 | AD10: =IF(AA10>0,1,0) -> 0 | AE10: =IF(enrollment!P10="","",enrollment!P10) -> Employer Change | AF10: =IF(enrollment!P10="",0,1) -> 1
A11: =enrollment!A11 -> M-000010 | B11: =enrollment!F11 -> Commercial | C11: =enrollment!I11 -> TN | D11: =enrollment!J11 -> Rural-Cannon | E11: =enrollment!L11 -> 50 | F11: {=_xlfn.IFS(E11<18,"0-17",E11<35,"18-34",E11<50,"35-49",E11<65,"50-64",TRUE,"65+")} -> 50-64 | G11: =enrollment!M11 -> M | H11: =enrollment!N11 -> 0.91 | I11: =enrollment!O11 -> 2233445566 | J11: =IFERROR(_xlfn.XLOOKUP(I11,providers!$B$2:$B$11,providers!$Q$2:$Q$11),"") -> 3.5 | K11: =SUMIFS(member_months!$F:$F,member_months!$A:$A,$A11) -> 12 | L11: =SUMIFS(claims!$Q:$Q,claims!$B:$B,$A11) -> 9566.78 | M11: =IF(K11=0,0,L11/K11) -> 797.23167 | N11: =SUMIFS(claims!$Q:$Q,claims!$B:$B,$A11,claims!$Z:$Z,"Inpatient") -> 0 | O11: =SUMIFS(claims!$Q:$Q,claims!$B:$B,$A11,claims!$Z:$Z,"ED") -> 8807.99 | P11: =SUMIFS(claims!$Q:$Q,claims!$B:$B,$A11,claims!$Z:$Z,"Specialty Rx") -> 0 | Q11: =IF($L11>=$U$2,1,0) -> 0 | S11: Blended PMPM | U11: =U6/U10 -> 1337.8931 | AA11: =COUNTIFS(claims!$B:$B,$A11,claims!$Z:$Z,"Behavioral Health") -> 1 | AB11: =COUNTIFS(claims!$B:$B,$A11,claims!$Z:$Z,"ED") -> 8 | AC11: =COUNTIFS(claims!$B:$B,$A11,claims!$Z:$Z,"Inpatient") -> 0 | AD11: =IF(AA11>0,1,0) -> 1 | AE11: =IF(enrollment!P11="","",enrollment!P11) | AF11: =IF(enrollment!P11="",0,1) -> 0
A12: =enrollment!A12 -> M-000011 | B12: =enrollment!F12 -> Commercial | C12: =enrollment!I12 -> KY | D12: =enrollment!J12 -> Warren | E12: =enrollment!L12 -> 72 | F12: {=_xlfn.IFS(E12<18,"0-17",E12<35,"18-34",E12<50,"35-49",E12<65,"50-64",TRUE,"65+")} -> 65+ | G12: =enrollment!M12 -> F | H12: =enrollment!N12 -> 2.01 | I12: =enrollment!O12 -> 9012345678 | J12: =IFERROR(_xlfn.XLOOKUP(I12,providers!$B$2:$B$11,providers!$Q$2:$Q$11),"") -> 4.3 | K12: =SUMIFS(member_months!$F:$F,member_months!$A:$A,$A12) -> 12 | L12: =SUMIFS(claims!$Q:$Q,claims!$B:$B,$A12) -> 2396.58 | M12: =IF(K12=0,0,L12/K12) -> 199.715 | N12: =SUMIFS(claims!$Q:$Q,claims!$B:$B,$A12,claims!$Z:$Z,"Inpatient") -> 0 | O12: =SUMIFS(claims!$Q:$Q,claims!$B:$B,$A12,claims!$Z:$Z,"ED") -> 2242.76 | P12: =SUMIFS(claims!$Q:$Q,claims!$B:$B,$A12,claims!$Z:$Z,"Specialty Rx") -> 0 | Q12: =IF($L12>=$U$2,1,0) -> 0 | AA12: =COUNTIFS(claims!$B:$B,$A12,claims!$Z:$Z,"Behavioral Health") -> 0 | AB12: =COUNTIFS(claims!$B:$B,$A12,claims!$Z:$Z,"ED") -> 2 | AC12: =COUNTIFS(claims!$B:$B,$A12,claims!$Z:$Z,"Inpatient") -> 0 | AD12: =IF(AA12>0,1,0) -> 0 | AE12: =IF(enrollment!P12="","",enrollment!P12) | AF12: =IF(enrollment!P12="",0,1) -> 0
A13: =enrollment!A13 -> M-000012 | B13: =enrollment!F13 -> Medicare Advantage | C13: =enrollment!I13 -> KY | D13: =enrollment!J13 -> Jefferson | E13: =enrollment!L13 -> 74 | F13: {=_xlfn.IFS(E13<18,"0-17",E13<35,"18-34",E13<50,"35-49",E13<65,"50-64",TRUE,"65+")} -> 65+ | G13: =enrollment!M13 -> F | H13: =enrollment!N13 -> 3.11 | I13: =enrollment!O13 -> 3456789012 | J13: =IFERROR(_xlfn.XLOOKUP(I13,providers!$B$2:$B$11,providers!$Q$2:$Q$11),"") -> 4 | K13: =SUMIFS(member_months!$F:$F,member_months!$A:$A,$A13) -> 10 | L13: =SUMIFS(claims!$Q:$Q,claims!$B:$B,$A13) -> 23944.18 | M13: =IF(K13=0,0,L13/K13) -> 2394.418 | N13: =SUMIFS(claims!$Q:$Q,claims!$B:$B,$A13,claims!$Z:$Z,"Inpatient") -> 21231.22 | O13: =SUMIFS(claims!$Q:$Q,claims!$B:$B,$A13,claims!$Z:$Z,"ED") -> 1081.46 | P13: =SUMIFS(claims!$Q:$Q,claims!$B:$B,$A13,claims!$Z:$Z,"Specialty Rx") -> 1104.9 | Q13: =IF($L13>=$U$2,1,0) -> 0 | S13: PMPM & HIGH-COST BY LOB | AA13: =COUNTIFS(claims!$B:$B,$A13,claims!$Z:$Z,"Behavioral Health") -> 0 | AB13: =COUNTIFS(claims!$B:$B,$A13,claims!$Z:$Z,"ED") -> 1 | AC13: =COUNTIFS(claims!$B:$B,$A13,claims!$Z:$Z,"Inpatient") -> 1 | AD13: =IF(AA13>0,1,0) -> 0 | AE13: =IF(enrollment!P13="","",enrollment!P13) | AF13: =IF(enrollment!P13="",0,1) -> 0
A14: =enrollment!A14 -> M-000013 | B14: =enrollment!F14 -> Marketplace | C14: =enrollment!I14 -> TN | D14: =enrollment!J14 -> Knox | E14: =enrollment!L14 -> 54 | F14: {=_xlfn.IFS(E14<18,"0-17",E14<35,"18-34",E14<50,"35-49",E14<65,"50-64",TRUE,"65+")} -> 50-64 | G14: =enrollment!M14 -> F | H14: =enrollment!N14 -> 0.98 | I14: =enrollment!O14 -> 7890123456 | J14: =IFERROR(_xlfn.XLOOKUP(I14,providers!$B$2:$B$11,providers!$Q$2:$Q$11),"") -> 3.9 | K14: =SUMIFS(member_months!$F:$F,member_months!$A:$A,$A14) -> 11 | L14: =SUMIFS(claims!$Q:$Q,claims!$B:$B,$A14) -> 3461.98 | M14: =IF(K14=0,0,L14/K14) -> 314.72545 | N14: =SUMIFS(claims!$Q:$Q,claims!$B:$B,$A14,claims!$Z:$Z,"Inpatient") -> 0 | O14: =SUMIFS(claims!$Q:$Q,claims!$B:$B,$A14,claims!$Z:$Z,"ED") -> 1274.49 | P14: =SUMIFS(claims!$Q:$Q,claims!$B:$B,$A14,claims!$Z:$Z,"Specialty Rx") -> 1742.76 | Q14: =IF($L14>=$U$2,1,0) -> 0 | S14: LOB | T14: Members | U14: Member Mos | V14: Allowed | W14: PMPM | X14: # High-cost | Y14: HC % of LOB $ | AA14: =COUNTIFS(claims!$B:$B,$A14,claims!$Z:$Z,"Behavioral Health") -> 1 | AB14: =COUNTIFS(claims!$B:$B,$A14,claims!$Z:$Z,"ED") -> 1 | AC14: =COUNTIFS(claims!$B:$B,$A14,claims!$Z:$Z,"Inpatient") -> 0 | AD14: =IF(AA14>0,1,0) -> 1 | AE14: =IF(enrollment!P14="","",enrollment!P14) | AF14: =IF(enrollment!P14="",0,1) -> 0
A15: =enrollment!A15 -> M-000014 | B15: =enrollment!F15 -> Commercial | C15: =enrollment!I15 -> KY | D15: =enrollment!J15 -> Hardin | E15: =enrollment!L15 -> 75 | F15: {=_xlfn.IFS(E15<18,"0-17",E15<35,"18-34",E15<50,"35-49",E15<65,"50-64",TRUE,"65+")} -> 65+ | G15: =enrollment!M15 -> M | H15: =enrollment!N15 -> 2.6 | I15: =enrollment!O15 -> 3456789012 | J15: =IFERROR(_xlfn.XLOOKUP(I15,providers!$B$2:$B$11,providers!$Q$2:$Q$11),"") -> 4 | K15: =SUMIFS(member_months!$F:$F,member_months!$A:$A,$A15) -> 12 | L15: =SUMIFS(claims!$Q:$Q,claims!$B:$B,$A15) -> 42510.65 | M15: =IF(K15=0,0,L15/K15) -> 3542.5542 | N15: =SUMIFS(claims!$Q:$Q,claims!$B:$B,$A15,claims!$Z:$Z,"Inpatient") -> 41635.03 | O15: =SUMIFS(claims!$Q:$Q,claims!$B:$B,$A15,claims!$Z:$Z,"ED") -> 0 | P15: =SUMIFS(claims!$Q:$Q,claims!$B:$B,$A15,claims!$Z:$Z,"Specialty Rx") -> 747.61 | Q15: =IF($L15>=$U$2,1,0) -> 0 | S15: Commercial | T15: =COUNTIFS($B$2:$B$801,$S15) -> 349 | U15: =SUMIFS($K$2:$K$801,$B$2:$B$801,$S15) -> 3733 | V15: =SUMIFS($L$2:$L$801,$B$2:$B$801,$S15) -> 4480145.7 | W15: =V15/U15 -> 1200.1462 | X15: =SUMIFS($Q$2:$Q$801,$B$2:$B$801,$S15) -> 13 | Y15: =SUMIFS($L$2:$L$801,$B$2:$B$801,$S15,$Q$2:$Q$801,1)/V15 -> 0.15735332 | AA15: =COUNTIFS(claims!$B:$B,$A15,claims!$Z:$Z,"Behavioral Health") -> 0 | AB15: =COUNTIFS(claims!$B:$B,$A15,claims!$Z:$Z,"ED") -> 0 | AC15: =COUNTIFS(claims!$B:$B,$A15,claims!$Z:$Z,"Inpatient") -> 2 | AD15: =IF(AA15>0,1,0) -> 0 | AE15: =IF(enrollment!P15="","",enrollment!P15) | AF15: =IF(enrollment!P15="",0,1) -> 0
A16: =enrollment!A16 -> M-000015 | B16: =enrollment!F16 -> Marketplace | C16: =enrollment!I16 -> TN | D16: =enrollment!J16 -> Davidson | E16: =enrollment!L16 -> 42 | F16: {=_xlfn.IFS(E16<18,"0-17",E16<35,"18-34",E16<50,"35-49",E16<65,"50-64",TRUE,"65+")} -> 35-49 | G16: =enrollment!M16 -> F | H16: =enrollment!N16 -> 1.24 | I16: =enrollment!O16 -> 5678901234 | J16: =IFERROR(_xlfn.XLOOKUP(I16,providers!$B$2:$B$11,providers!$Q$2:$Q$11),"") -> 3.8 | K16: =SUMIFS(member_months!$F:$F,member_months!$A:$A,$A16) -> 7 | L16: =SUMIFS(claims!$Q:$Q,claims!$B:$B,$A16) -> 17078.79 | M16: =IF(K16=0,0,L16/K16) -> 2439.8271 | N16: =SUMIFS(claims!$Q:$Q,claims!$B:$B,$A16,claims!$Z:$Z,"Inpatient") -> 14057.22 | O16: =SUMIFS(claims!$Q:$Q,claims!$B:$B,$A16,claims!$Z:$Z,"ED") -> 1020.44 | P16: =SUMIFS(claims!$Q:$Q,claims!$B:$B,$A16,claims!$Z:$Z,"Specialty Rx") -> 909.78 | Q16: =IF($L16>=$U$2,1,0) -> 0 | S16: Marketplace | T16: =COUNTIFS($B$2:$B$801,$S16) -> 299 | U16: =SUMIFS($K$2:$K$801,$B$2:$B$801,$S16) -> 3088 | V16: =SUMIFS($L$2:$L$801,$B$2:$B$801,$S16) -> 4230001.4 | W16: =V16/U16 -> 1369.8191 | X16: =SUMIFS($Q$2:$Q$801,$B$2:$B$801,$S16) -> 15 | Y16: =SUMIFS($L$2:$L$801,$B$2:$B$801,$S16,$Q$2:$Q$801,1)/V16 -> 0.20440639 | AA16: =COUNTIFS(claims!$B:$B,$A16,claims!$Z:$Z,"Behavioral Health") -> 2 | AB16: =COUNTIFS(claims!$B:$B,$A16,claims!$Z:$Z,"ED") -> 1 | AC16: =COUNTIFS(claims!$B:$B,$A16,claims!$Z:$Z,"Inpatient") -> 1 | AD16: =IF(AA16>0,1,0) -> 1 | AE16: =IF(enrollment!P16="","",enrollment!P16) -> Premium Affordability | AF16: =IF(enrollment!P16="",0,1) -> 1
A17: =enrollment!A17 -> M-000016 | B17: =enrollment!F17 -> Marketplace | C17: =enrollment!I17 -> TN | D17: =enrollment!J17 -> Knox | E17: =enrollment!L17 -> 82 | F17: {=_xlfn.IFS(E17<18,"0-17",E17<35,"18-34",E17<50,"35-49",E17<65,"50-64",TRUE,"65+")} -> 65+ | G17: =enrollment!M17 -> M | H17: =enrollment!N17 -> 3.21 | I17: =enrollment!O17 -> 5678901234 | J17: =IFERROR(_xlfn.XLOOKUP(I17,providers!$B$2:$B$11,providers!$Q$2:$Q$11),"") -> 3.8 | K17: =SUMIFS(member_months!$F:$F,member_months!$A:$A,$A17) -> 12 | L17: =SUMIFS(claims!$Q:$Q,claims!$B:$B,$A17) -> 4010.99 | M17: =IF(K17=0,0,L17/K17) -> 334.24917 | N17: =SUMIFS(claims!$Q:$Q,claims!$B:$B,$A17,claims!$Z:$Z,"Inpatient") -> 0 | O17: =SUMIFS(claims!$Q:$Q,claims!$B:$B,$A17,claims!$Z:$Z,"ED") -> 3479.86 | P17: =SUMIFS(claims!$Q:$Q,claims!$B:$B,$A17,claims!$Z:$Z,"Specialty Rx") -> 0 | Q17: =IF($L17>=$U$2,1,0) -> 0 | S17: Medicare Advantage | T17: =COUNTIFS($B$2:$B$801,$S17) -> 152 | U17: =SUMIFS($K$2:$K$801,$B$2:$B$801,$S17) -> 1641 | V17: =SUMIFS($L$2:$L$801,$B$2:$B$801,$S17) -> 2611104.8 | W17: =V17/U17 -> 1591.1668 | X17: =SUMIFS($Q$2:$Q$801,$B$2:$B$801,$S17) -> 12 | Y17: =SUMIFS($L$2:$L$801,$B$2:$B$801,$S17,$Q$2:$Q$801,1)/V17 -> 0.28635334 | AA17: =COUNTIFS(claims!$B:$B,$A17,claims!$Z:$Z,"Behavioral Health") -> 0 | AB17: =COUNTIFS(claims!$B:$B,$A17,claims!$Z:$Z,"ED") -> 3 | AC17: =COUNTIFS(claims!$B:$B,$A17,claims!$Z:$Z,"Inpatient") -> 0 | AD17: =IF(AA17>0,1,0) -> 0 | AE17: =IF(enrollment!P17="","",enrollment!P17) | AF17: =IF(enrollment!P17="",0,1) -> 0
A18: =enrollment!A18 -> M-000017 | B18: =enrollment!F18 -> Medicare Advantage | C18: =enrollment!I18 -> GA | D18: =enrollment!J18 -> Cherokee | E18: =enrollment!L18 -> 65 | F18: {=_xlfn.IFS(E18<18,"0-17",E18<35,"18-34",E18<50,"35-49",E18<65,"50-64",TRUE,"65+")} -> 65+ | G18: =enrollment!M18 -> F | H18: =enrollment!N18 -> 3.67 | I18: =enrollment!O18 -> 8901234567 | J18: =IFERROR(_xlfn.XLOOKUP(I18,providers!$B$2:$B$11,providers!$Q$2:$Q$11),"") -> 3.7 | K18: =SUMIFS(member_months!$F:$F,member_months!$A:$A,$A18) -> 10 | L18: =SUMIFS(claims!$Q:$Q,claims!$B:$B,$A18) -> 1711.61 | M18: =IF(K18=0,0,L18/K18) -> 171.161 | N18: =SUMIFS(claims!$Q:$Q,claims!$B:$B,$A18,claims!$Z:$Z,"Inpatient") -> 0 | O18: =SUMIFS(claims!$Q:$Q,claims!$B:$B,$A18,claims!$Z:$Z,"ED") -> 1229.36 | P18: =SUMIFS(claims!$Q:$Q,claims!$B:$B,$A18,claims!$Z:$Z,"Specialty Rx") -> 0 | Q18: =IF($L18>=$U$2,1,0) -> 0 | S18: Total | T18: =SUM(T15:T17) -> 800 | U18: =SUM(U15:U17) -> 8462 | V18: =SUM(V15:V17) -> 11321252 | W18: =V18/U18 -> 1337.8931 | X18: =SUM(X15:X17) -> 40 | Y18: =SUMIFS($L$2:$L$801,$Q$2:$Q$801,1)/V18 -> 0.20468617 | AA18: =COUNTIFS(claims!$B:$B,$A18,claims!$Z:$Z,"Behavioral Health") -> 1 | AB18: =COUNTIFS(claims!$B:$B,$A18,claims!$Z:$Z,"ED") -> 1 | AC18: =COUNTIFS(claims!$B:$B,$A18,claims!$Z:$Z,"Inpatient") -> 0 | AD18: =IF(AA18>0,1,0) -> 1 | AE18: =IF(enrollment!P18="","",enrollment!P18) | AF18: =IF(enrollment!P18="",0,1) -> 0
A19: =enrollment!A19 -> M-000018 | B19: =enrollment!F19 -> Commercial | C19: =enrollment!I19 -> TN | D19: =enrollment!J19 -> Davidson | E19: =enrollment!L19 -> 35 | F19: {=_xlfn.IFS(E19<18,"0-17",E19<35,"18-34",E19<50,"35-49",E19<65,"50-64",TRUE,"65+")} -> 35-49 | G19: =enrollment!M19 -> F | H19: =enrollment!N19 -> 1.11 | I19: =enrollment!O19 -> 5678901234 | J19: =IFERROR(_xlfn.XLOOKUP(I19,providers!$B$2:$B$11,providers!$Q$2:$Q$11),"") -> 3.8 | K19: =SUMIFS(member_months!$F:$F,member_months!$A:$A,$A19) -> 9 | L19: =SUMIFS(claims!$Q:$Q,claims!$B:$B,$A19) -> 21544.32 | M19: =IF(K19=0,0,L19/K19) -> 2393.8133 | N19: =SUMIFS(claims!$Q:$Q,claims!$B:$B,$A19,claims!$Z:$Z,"Inpatient") -> 18187.45 | O19: =SUMIFS(claims!$Q:$Q,claims!$B:$B,$A19,claims!$Z:$Z,"ED") -> 0 | P19: =SUMIFS(claims!$Q:$Q,claims!$B:$B,$A19,claims!$Z:$Z,"Specialty Rx") -> 1770.26 | Q19: =IF($L19>=$U$2,1,0) -> 0 | AA19: =COUNTIFS(claims!$B:$B,$A19,claims!$Z:$Z,"Behavioral Health") -> 1 | AB19: =COUNTIFS(claims!$B:$B,$A19,claims!$Z:$Z,"ED") -> 0 | AC19: =COUNTIFS(claims!$B:$B,$A19,claims!$Z:$Z,"Inpatient") -> 1 | AD19: =IF(AA19>0,1,0) -> 1 | AE19: =IF(enrollment!P19="","",enrollment!P19) -> Premium Affordability | AF19: =IF(enrollment!P19="",0,1) -> 1
A20: =enrollment!A20 -> M-000019 | B20: =enrollment!F20 -> Commercial | C20: =enrollment!I20 -> OH | D20: =enrollment!J20 -> Franklin | E20: =enrollment!L20 -> 41 | F20: {=_xlfn.IFS(E20<18,"0-17",E20<35,"18-34",E20<50,"35-49",E20<65,"50-64",TRUE,"65+")} -> 35-49 | G20: =enrollment!M20 -> M | H20: =enrollment!N20 -> 0.93 | I20: =enrollment!O20 -> 6789012345 | J20: =IFERROR(_xlfn.XLOOKUP(I20,providers!$B$2:$B$11,providers!$Q$2:$Q$11),"") -> 4.1 | K20: =SUMIFS(member_months!$F:$F,member_months!$A:$A,$A20) -> 10 | L20: =SUMIFS(claims!$Q:$Q,claims!$B:$B,$A20) -> 2215.33 | M20: =IF(K20=0,0,L20/K20) -> 221.533 | N20: =SUMIFS(claims!$Q:$Q,claims!$B:$B,$A20,claims!$Z:$Z,"Inpatient") -> 0 | O20: =SUMIFS(claims!$Q:$Q,claims!$B:$B,$A20,claims!$Z:$Z,"ED") -> 0 | P20: =SUMIFS(claims!$Q:$Q,claims!$B:$B,$A20,claims!$Z:$Z,"Specialty Rx") -> 1132.07 | Q20: =IF($L20>=$U$2,1,0) -> 0 | S20: PMPM & HIGH-COST BY STATE | AA20: =COUNTIFS(claims!$B:$B,$A20,claims!$Z:$Z,"Behavioral Health") -> 1 | AB20: =COUNTIFS(claims!$B:$B,$A20,claims!$Z:$Z,"ED") -> 0 | AC20: =COUNTIFS(claims!$B:$B,$A20,claims!$Z:$Z,"Inpatient") -> 0 | AD20: =IF(AA20>0,1,0) -> 1 | AE20: =IF(enrollment!P20="","",enrollment!P20) | AF20: =IF(enrollment!P20="",0,1) -> 0
A21: =enrollment!A21 -> M-000020 | B21: =enrollment!F21 -> Medicare Advantage | C21: =enrollment!I21 -> TN | D21: =enrollment!J21 -> Rural-Cannon | E21: =enrollment!L21 -> 84 | F21: {=_xlfn.IFS(E21<18,"0-17",E21<35,"18-34",E21<50,"35-49",E21<65,"50-64",TRUE,"65+")} -> 65+ | G21: =enrollment!M21 -> M | H21: =enrollment!N21 -> 2.7 | I21: =enrollment!O21 -> 2233445566 | J21: =IFERROR(_xlfn.XLOOKUP(I21,providers!$B$2:$B$11,providers!$Q$2:$Q$11),"") -> 3.5 | K21: =SUMIFS(member_months!$F:$F,member_months!$A:$A,$A21) -> 12 | L21: =SUMIFS(claims!$Q:$Q,claims!$B:$B,$A21) -> 11451.14 | M21: =IF(K21=0,0,L21/K21) -> 954.26167 | N21: =SUMIFS(claims!$Q:$Q,claims!$B:$B,$A21,claims!$Z:$Z,"Inpatient") -> 0 | O21: =SUMIFS(claims!$Q:$Q,claims!$B:$B,$A21,claims!$Z:$Z,"ED") -> 11257.01 | P21: =SUMIFS(claims!$Q:$Q,claims!$B:$B,$A21,claims!$Z:$Z,"Specialty Rx") -> 0 | Q21: =IF($L21>=$U$2,1,0) -> 0 | S21: State | T21: Members | U21: Member Mos | V21: Allowed | W21: PMPM | X21: # High-cost | Y21: HC % of state $ | AA21: =COUNTIFS(claims!$B:$B,$A21,claims!$Z:$Z,"Behavioral Health") -> 1 | AB21: =COUNTIFS(claims!$B:$B,$A21,claims!$Z:$Z,"ED") -> 10 | AC21: =COUNTIFS(claims!$B:$B,$A21,claims!$Z:$Z,"Inpatient") -> 0 | AD21: =IF(AA21>0,1,0) -> 1 | AE21: =IF(enrollment!P21="","",enrollment!P21) | AF21: =IF(enrollment!P21="",0,1) -> 0
A22: =enrollment!A22 -> M-000021 | B22: =enrollment!F22 -> Commercial | C22: =enrollment!I22 -> KY | D22: =enrollment!J22 -> Jefferson | E22: =enrollment!L22 -> 33 | F22: {=_xlfn.IFS(E22<18,"0-17",E22<35,"18-34",E22<50,"35-49",E22<65,"50-64",TRUE,"65+")} -> 18-34 | G22: =enrollment!M22 -> F | H22: =enrollment!N22 -> 0.72 | I22: =enrollment!O22 -> 9012345678 | J22: =IFERROR(_xlfn.XLOOKUP(I22,providers!$B$2:$B$11,providers!$Q$2:$Q$11),"") -> 4.3 | K22: =SUMIFS(member_months!$F:$F,member_months!$A:$A,$A22) -> 12 | L22: =SUMIFS(claims!$Q:$Q,claims!$B:$B,$A22) -> 31297.49 | M22: =IF(K22=0,0,L22/K22) -> 2608.1242 | N22: =SUMIFS(claims!$Q:$Q,claims!$B:$B,$A22,claims!$Z:$Z,"Inpatient") -> 30396.44 | O22: =SUMIFS(claims!$Q:$Q,claims!$B:$B,$A22,claims!$Z:$Z,"ED") -> 0 | P22: =SUMIFS(claims!$Q:$Q,claims!$B:$B,$A22,claims!$Z:$Z,"Specialty Rx") -> 0 | Q22: =IF($L22>=$U$2,1,0) -> 0 | S22: KY | T22: =COUNTIFS($C$2:$C$801,$S22) -> 182 | U22: =SUMIFS($K$2:$K$801,$C$2:$C$801,$S22) -> 1911 | V22: =SUMIFS($L$2:$L$801,$C$2:$C$801,$S22) -> 2600619.4 | W22: =V22/U22 -> 1360.8684 | X22: =SUMIFS($Q$2:$Q$801,$C$2:$C$801,$S22) -> 9 | Y22: =SUMIFS($L$2:$L$801,$C$2:$C$801,$S22,$Q$2:$Q$801,1)/V22 -> 0.22720377 | AA22: =COUNTIFS(claims!$B:$B,$A22,claims!$Z:$Z,"Behavioral Health") -> 0 | AB22: =COUNTIFS(claims!$B:$B,$A22,claims!$Z:$Z,"ED") -> 0 | AC22: =COUNTIFS(claims!$B:$B,$A22,claims!$Z:$Z,"Inpatient") -> 2 | AD22: =IF(AA22>0,1,0) -> 0 | AE22: =IF(enrollment!P22="","",enrollment!P22) | AF22: =IF(enrollment!P22="",0,1) -> 0
A23: =enrollment!A23 -> M-000022 | B23: =enrollment!F23 -> Commercial | C23: =enrollment!I23 -> OH | D23: =enrollment!J23 -> Cuyahoga | E23: =enrollment!L23 -> 75 | F23: {=_xlfn.IFS(E23<18,"0-17",E23<35,"18-34",E23<50,"35-49",E23<65,"50-64",TRUE,"65+")} -> 65+ | G23: =enrollment!M23 -> M | H23: =enrollment!N23 -> 2.53 | I23: =enrollment!O23 -> 2345678901 | J23: =IFERROR(_xlfn.XLOOKUP(I23,providers!$B$2:$B$11,providers!$Q$2:$Q$11),"") -> 4.2 | K23: =SUMIFS(member_months!$F:$F,member_months!$A:$A,$A23) -> 10 | L23: =SUMIFS(claims!$Q:$Q,claims!$B:$B,$A23) -> 36502.46 | M23: =IF(K23=0,0,L23/K23) -> 3650.246 | N23: =SUMIFS(claims!$Q:$Q,claims!$B:$B,$A23,claims!$Z:$Z,"Inpatient") -> 34570.53 | O23: =SUMIFS(claims!$Q:$Q,claims!$B:$B,$A23,claims!$Z:$Z,"ED") -> 883.04 | P23: =SUMIFS(claims!$Q:$Q,claims!$B:$B,$A23,claims!$Z:$Z,"Specialty Rx") -> 769.27 | Q23: =IF($L23>=$U$2,1,0) -> 0 | S23: GA | T23: =COUNTIFS($C$2:$C$801,$S23) -> 194 | U23: =SUMIFS($K$2:$K$801,$C$2:$C$801,$S23) -> 2043 | V23: =SUMIFS($L$2:$L$801,$C$2:$C$801,$S23) -> 2772066.4 | W23: =V23/U23 -> 1356.8607 | X23: =SUMIFS($Q$2:$Q$801,$C$2:$C$801,$S23) -> 10 | Y23: =SUMIFS($L$2:$L$801,$C$2:$C$801,$S23,$Q$2:$Q$801,1)/V23 -> 0.19819586 | AA23: =COUNTIFS(claims!$B:$B,$A23,claims!$Z:$Z,"Behavioral Health") -> 0 | AB23: =COUNTIFS(claims!$B:$B,$A23,claims!$Z:$Z,"ED") -> 1 | AC23: =COUNTIFS(claims!$B:$B,$A23,claims!$Z:$Z,"Inpatient") -> 2 | AD23: =IF(AA23>0,1,0) -> 0 | AE23: =IF(enrollment!P23="","",enrollment!P23) | AF23: =IF(enrollment!P23="",0,1) -> 0
A24: =enrollment!A24 -> M-000023 | B24: =enrollment!F24 -> Marketplace | C24: =enrollment!I24 -> KY | D24: =enrollment!J24 -> Jefferson | E24: =enrollment!L24 -> 45 | F24: {=_xlfn.IFS(E24<18,"0-17",E24<35,"18-34",E24<50,"35-49",E24<65,"50-64",TRUE,"65+")} -> 35-49 | G24: =enrollment!M24 -> F | H24: =enrollment!N24 -> 1.32 | I24: =enrollment!O24 -> 3456789012 | J24: =IFERROR(_xlfn.XLOOKUP(I24,providers!$B$2:$B$11,providers!$Q$2:$Q$11),"") -> 4 | K24: =SUMIFS(member_months!$F:$F,member_months!$A:$A,$A24) -> 11 | L24: =SUMIFS(claims!$Q:$Q,claims!$B:$B,$A24) -> 26060.63 | M24: =IF(K24=0,0,L24/K24) -> 2369.1482 | N24: =SUMIFS(claims!$Q:$Q,claims!$B:$B,$A24,claims!$Z:$Z,"Inpatient") -> 19822.22 | O24: =SUMIFS(claims!$Q:$Q,claims!$B:$B,$A24,claims!$Z:$Z,"ED") -> 2445.36 | P24: =SUMIFS(claims!$Q:$Q,claims!$B:$B,$A24,claims!$Z:$Z,"Specialty Rx") -> 3332.78 | Q24: =IF($L24>=$U$2,1,0) -> 0 | S24: TN | T24: =COUNTIFS($C$2:$C$801,$S24) -> 204 | U24: =SUMIFS($K$2:$K$801,$C$2:$C$801,$S24) -> 2160 | V24: =SUMIFS($L$2:$L$801,$C$2:$C$801,$S24) -> 2757008.3 | W24: =V24/U24 -> 1276.3928 | X24: =SUMIFS($Q$2:$Q$801,$C$2:$C$801,$S24) -> 12 | Y24: =SUMIFS($L$2:$L$801,$C$2:$C$801,$S24,$Q$2:$Q$801,1)/V24 -> 0.24345866 | AA24: =COUNTIFS(claims!$B:$B,$A24,claims!$Z:$Z,"Behavioral Health") -> 1 | AB24: =COUNTIFS(claims!$B:$B,$A24,claims!$Z:$Z,"ED") -> 2 | AC24: =COUNTIFS(claims!$B:$B,$A24,claims!$Z:$Z,"Inpatient") -> 1 | AD24: =IF(AA24>0,1,0) -> 1 | AE24: =IF(enrollment!P24="","",enrollment!P24) | AF24: =IF(enrollment!P24="",0,1) -> 0
A25: =enrollment!A25 -> M-000024 | B25: =enrollment!F25 -> Marketplace | C25: =enrollment!I25 -> OH | D25: =enrollment!J25 -> Franklin | E25: =enrollment!L25 -> 79 | F25: {=_xlfn.IFS(E25<18,"0-17",E25<35,"18-34",E25<50,"35-49",E25<65,"50-64",TRUE,"65+")} -> 65+ | G25: =enrollment!M25 -> F | H25: =enrollment!N25 -> 2.23 | I25: =enrollment!O25 -> 6789012345 | J25: =IFERROR(_xlfn.XLOOKUP(I25,providers!$B$2:$B$11,providers!$Q$2:$Q$11),"") -> 4.1 | K25: =SUMIFS(member_months!$F:$F,member_months!$A:$A,$A25) -> 9 | L25: =SUMIFS(claims!$Q:$Q,claims!$B:$B,$A25) -> 21822.16 | M25: =IF(K25=0,0,L25/K25) -> 2424.6844 | N25: =SUMIFS(claims!$Q:$Q,claims!$B:$B,$A25,claims!$Z:$Z,"Inpatient") -> 17977.44 | O25: =SUMIFS(claims!$Q:$Q,claims!$B:$B,$A25,claims!$Z:$Z,"ED") -> 1201.91 | P25: =SUMIFS(claims!$Q:$Q,claims!$B:$B,$A25,claims!$Z:$Z,"Specialty Rx") -> 1768.12 | Q25: =IF($L25>=$U$2,1,0) -> 0 | S25: OH | T25: =COUNTIFS($C$2:$C$801,$S25) -> 220 | U25: =SUMIFS($K$2:$K$801,$C$2:$C$801,$S25) -> 2348 | V25: =SUMIFS($L$2:$L$801,$C$2:$C$801,$S25) -> 3191557.7 | W25: =V25/U25 -> 1359.2665 | X25: =SUMIFS($Q$2:$Q$801,$C$2:$C$801,$S25) -> 9 | Y25: =SUMIFS($L$2:$L$801,$C$2:$C$801,$S25,$Q$2:$Q$801,1)/V25 -> 0.1584817 | AA25: =COUNTIFS(claims!$B:$B,$A25,claims!$Z:$Z,"Behavioral Health") -> 1 | AB25: =COUNTIFS(claims!$B:$B,$A25,claims!$Z:$Z,"ED") -> 1 | AC25: =COUNTIFS(claims!$B:$B,$A25,claims!$Z:$Z,"Inpatient") -> 1 | AD25: =IF(AA25>0,1,0) -> 1 | AE25: =IF(enrollment!P25="","",enrollment!P25) -> Premium Affordability | AF25: =IF(enrollment!P25="",0,1) -> 1
A26: =enrollment!A26 -> M-000025 | B26: =enrollment!F26 -> Marketplace | C26: =enrollment!I26 -> TN | D26: =enrollment!J26 -> Rural-Cannon | E26: =enrollment!L26 -> 46 | F26: {=_xlfn.IFS(E26<18,"0-17",E26<35,"18-34",E26<50,"35-49",E26<65,"50-64",TRUE,"65+")} -> 35-49 | G26: =enrollment!M26 -> F | H26: =enrollment!N26 -> 1.31 | I26: =enrollment!O26 -> 2233445566 | J26: =IFERROR(_xlfn.XLOOKUP(I26,providers!$B$2:$B$11,providers!$Q$2:$Q$11),"") -> 3.5 | K26: =SUMIFS(member_months!$F:$F,member_months!$A:$A,$A26) -> 10 | L26: =SUMIFS(claims!$Q:$Q,claims!$B:$B,$A26) -> 4310.33 | M26: =IF(K26=0,0,L26/K26) -> 431.033 | N26: =SUMIFS(claims!$Q:$Q,claims!$B:$B,$A26,claims!$Z:$Z,"Inpatient") -> 0 | O26: =SUMIFS(claims!$Q:$Q,claims!$B:$B,$A26,claims!$Z:$Z,"ED") -> 3528.49 | P26: =SUMIFS(claims!$Q:$Q,claims!$B:$B,$A26,claims!$Z:$Z,"Specialty Rx") -> 0 | Q26: =IF($L26>=$U$2,1,0) -> 0 | S26: Total | T26: =SUM(T22:T25) -> 800 | U26: =SUM(U22:U25) -> 8462 | V26: =SUM(V22:V25) -> 11321252 | W26: =V26/U26 -> 1337.8931 | X26: =SUM(X22:X25) -> 40 | Y26: =SUMIFS($L$2:$L$801,$Q$2:$Q$801,1)/V26 -> 0.20468617 | AA26: =COUNTIFS(claims!$B:$B,$A26,claims!$Z:$Z,"Behavioral Health") -> 2 | AB26: =COUNTIFS(claims!$B:$B,$A26,claims!$Z:$Z,"ED") -> 3 | AC26: =COUNTIFS(claims!$B:$B,$A26,claims!$Z:$Z,"Inpatient") -> 0 | AD26: =IF(AA26>0,1,0) -> 1 | AE26: =IF(enrollment!P26="","",enrollment!P26) | AF26: =IF(enrollment!P26="",0,1) -> 0
A27: =enrollment!A27 -> M-000026 | B27: =enrollment!F27 -> Medicare Advantage | C27: =enrollment!I27 -> OH | D27: =enrollment!J27 -> Cuyahoga | E27: =enrollment!L27 -> 72 | F27: {=_xlfn.IFS(E27<18,"0-17",E27<35,"18-34",E27<50,"35-49",E27<65,"50-64",TRUE,"65+")} -> 65+ | G27: =enrollment!M27 -> M | H27: =enrollment!N27 -> 3.11 | I27: =enrollment!O27 -> 6789012345 | J27: =IFERROR(_xlfn.XLOOKUP(I27,providers!$B$2:$B$11,providers!$Q$2:$Q$11),"") -> 4.1 | K27: =SUMIFS(member_months!$F:$F,member_months!$A:$A,$A27) -> 12 | L27: =SUMIFS(claims!$Q:$Q,claims!$B:$B,$A27) -> 2788.55 | M27: =IF(K27=0,0,L27/K27) -> 232.37917 | N27: =SUMIFS(claims!$Q:$Q,claims!$B:$B,$A27,claims!$Z:$Z,"Inpatient") -> 0 | O27: =SUMIFS(claims!$Q:$Q,claims!$B:$B,$A27,claims!$Z:$Z,"ED") -> 0 | P27: =SUMIFS(claims!$Q:$Q,claims!$B:$B,$A27,claims!$Z:$Z,"Specialty Rx") -> 1657.15 | Q27: =IF($L27>=$U$2,1,0) -> 0 | AA27: =COUNTIFS(claims!$B:$B,$A27,claims!$Z:$Z,"Behavioral Health") -> 0 | AB27: =COUNTIFS(claims!$B:$B,$A27,claims!$Z:$Z,"ED") -> 0 | AC27: =COUNTIFS(claims!$B:$B,$A27,claims!$Z:$Z,"Inpatient") -> 0 | AD27: =IF(AA27>0,1,0) -> 0 | AE27: =IF(enrollment!P27="","",enrollment!P27) | AF27: =IF(enrollment!P27="",0,1) -> 0
A28: =enrollment!A28 -> M-000027 | B28: =enrollment!F28 -> Marketplace | C28: =enrollment!I28 -> GA | D28: =enrollment!J28 -> Fulton | E28: =enrollment!L28 -> 71 | F28: {=_xlfn.IFS(E28<18,"0-17",E28<35,"18-34",E28<50,"35-49",E28<65,"50-64",TRUE,"65+")} -> 65+ | G28: =enrollment!M28 -> M | H28: =enrollment!N28 -> 3.6 | I28: =enrollment!O28 -> 8901234567 | J28: =IFERROR(_xlfn.XLOOKUP(I28,providers!$B$2:$B$11,providers!$Q$2:$Q$11),"") -> 3.7 | K28: =SUMIFS(member_months!$F:$F,member_months!$A:$A,$A28) -> 10 | L28: =SUMIFS(claims!$Q:$Q,claims!$B:$B,$A28) -> 23890.73 | M28: =IF(K28=0,0,L28/K28) -> 2389.073 | N28: =SUMIFS(claims!$Q:$Q,claims!$B:$B,$A28,claims!$Z:$Z,"Inpatient") -> 20943.86 | O28: =SUMIFS(claims!$Q:$Q,claims!$B:$B,$A28,claims!$Z:$Z,"ED") -> 1394.16 | P28: =SUMIFS(claims!$Q:$Q,claims!$B:$B,$A28,claims!$Z:$Z,"Specialty Rx") -> 842.29 | Q28: =IF($L28>=$U$2,1,0) -> 0 | AA28: =COUNTIFS(claims!$B:$B,$A28,claims!$Z:$Z,"Behavioral Health") -> 0 | AB28: =COUNTIFS(claims!$B:$B,$A28,claims!$Z:$Z,"ED") -> 1 | AC28: =COUNTIFS(claims!$B:$B,$A28,claims!$Z:$Z,"Inpatient") -> 1 | AD28: =IF(AA28>0,1,0) -> 0 | AE28: =IF(enrollment!P28="","",enrollment!P28) | AF28: =IF(enrollment!P28="",0,1) -> 0
A29: =enrollment!A29 -> M-000028 | B29: =enrollment!F29 -> Commercial | C29: =enrollment!I29 -> TN | D29: =enrollment!J29 -> Davidson | E29: =enrollment!L29 -> 72 | F29: {=_xlfn.IFS(E29<18,"0-17",E29<35,"18-34",E29<50,"35-49",E29<65,"50-64",TRUE,"65+")} -> 65+ | G29: =enrollment!M29 -> F | H29: =enrollment!N29 -> 2.15 | I29: =enrollment!O29 -> 5678901234 | J29: =IFERROR(_xlfn.XLOOKUP(I29,providers!$B$2:$B$11,providers!$Q$2:$Q$11),"") -> 3.8 | K29: =SUMIFS(member_months!$F:$F,member_months!$A:$A,$A29) -> 10 | L29: =SUMIFS(claims!$Q:$Q,claims!$B:$B,$A29) -> 17721.04 | M29: =IF(K29=0,0,L29/K29) -> 1772.104 | N29: =SUMIFS(claims!$Q:$Q,claims!$B:$B,$A29,claims!$Z:$Z,"Inpatient") -> 17435.93 | O29: =SUMIFS(claims!$Q:$Q,claims!$B:$B,$A29,claims!$Z:$Z,"ED") -> 0 | P29: =SUMIFS(claims!$Q:$Q,claims!$B:$B,$A29,claims!$Z:$Z,"Specialty Rx") -> 0 | Q29: =IF($L29>=$U$2,1,0) -> 0 | AA29: =COUNTIFS(claims!$B:$B,$A29,claims!$Z:$Z,"Behavioral Health") -> 0 | AB29: =COUNTIFS(claims!$B:$B,$A29,claims!$Z:$Z,"ED") -> 0 | AC29: =COUNTIFS(claims!$B:$B,$A29,claims!$Z:$Z,"Inpatient") -> 1 | AD29: =IF(AA29>0,1,0) -> 0 | AE29: =IF(enrollment!P29="","",enrollment!P29) | AF29: =IF(enrollment!P29="",0,1) -> 0
A30: =enrollment!A30 -> M-000029 | B30: =enrollment!F30 -> Marketplace | C30: =enrollment!I30 -> OH | D30: =enrollment!J30 -> Cuyahoga | E30: =enrollment!L30 -> 80 | F30: {=_xlfn.IFS(E30<18,"0-17",E30<35,"18-34",E30<50,"35-49",E30<65,"50-64",TRUE,"65+")} -> 65+ | G30: =enrollment!M30 -> M | H30: =enrollment!N30 -> 2.84 | I30: =enrollment!O30 -> 6789012345 | J30: =IFERROR(_xlfn.XLOOKUP(I30,providers!$B$2:$B$11,providers!$Q$2:$Q$11),"") -> 4.1 | K30: =SUMIFS(member_months!$F:$F,member_months!$A:$A,$A30) -> 11 | L30: =SUMIFS(claims!$Q:$Q,claims!$B:$B,$A30) -> 2936.92 | M30: =IF(K30=0,0,L30/K30) -> 266.99273 | N30: =SUMIFS(claims!$Q:$Q,claims!$B:$B,$A30,claims!$Z:$Z,"Inpatient") -> 0 | O30: =SUMIFS(claims!$Q:$Q,claims!$B:$B,$A30,claims!$Z:$Z,"ED") -> 2327.46 | P30: =SUMIFS(claims!$Q:$Q,claims!$B:$B,$A30,claims!$Z:$Z,"Specialty Rx") -> 0 | Q30: =IF($L30>=$U$2,1,0) -> 0 | AA30: =COUNTIFS(claims!$B:$B,$A30,claims!$Z:$Z,"Behavioral Health") -> 1 | AB30: =COUNTIFS(claims!$B:$B,$A30,claims!$Z:$Z,"ED") -> 2 | AC30: =COUNTIFS(claims!$B:$B,$A30,claims!$Z:$Z,"Inpatient") -> 0 | AD30: =IF(AA30>0,1,0) -> 1 | AE30: =IF(enrollment!P30="","",enrollment!P30) | AF30: =IF(enrollment!P30="",0,1) -> 0
A31: =enrollment!A31 -> M-000030 | B31: =enrollment!F31 -> Commercial | C31: =enrollment!I31 -> TN | D31: =enrollment!J31 -> Knox | E31: =enrollment!L31 -> 60 | F31: {=_xlfn.IFS(E31<18,"0-17",E31<35,"18-34",E31<50,"35-49",E31<65,"50-64",TRUE,"65+")} -> 50-64 | G31: =enrollment!M31 -> M | H31: =enrollment!N31 -> 1.05 | I31: =enrollment!O31 -> 7890123456 | J31: =IFERROR(_xlfn.XLOOKUP(I31,providers!$B$2:$B$11,providers!$Q$2:$Q$11),"") -> 3.9 | K31: =SUMIFS(member_months!$F:$F,member_months!$A:$A,$A31) -> 12 | L31: =SUMIFS(claims!$Q:$Q,claims!$B:$B,$A31) -> 3469.88 | M31: =IF(K31=0,0,L31/K31) -> 289.15667 | N31: =SUMIFS(claims!$Q:$Q,claims!$B:$B,$A31,claims!$Z:$Z,"Inpatient") -> 0 | O31: =SUMIFS(claims!$Q:$Q,claims!$B:$B,$A31,claims!$Z:$Z,"ED") -> 1222.1 | P31: =SUMIFS(claims!$Q:$Q,claims!$B:$B,$A31,claims!$Z:$Z,"Specialty Rx") -> 1962.6 | Q31: =IF($L31>=$U$2,1,0) -> 0 | AA31: =COUNTIFS(claims!$B:$B,$A31,claims!$Z:$Z,"Behavioral Health") -> 0 | AB31: =COUNTIFS(claims!$B:$B,$A31,claims!$Z:$Z,"ED") -> 1 | AC31: =COUNTIFS(claims!$B:$B,$A31,claims!$Z:$Z,"Inpatient") -> 0 | AD31: =IF(AA31>0,1,0) -> 0 | AE31: =IF(enrollment!P31="","",enrollment!P31) | AF31: =IF(enrollment!P31="",0,1) -> 0
A32: =enrollment!A32 -> M-000031 | B32: =enrollment!F32 -> Commercial | C32: =enrollment!I32 -> TN | D32: =enrollment!J32 -> Rural-Cannon | E32: =enrollment!L32 -> 53 | F32: {=_xlfn.IFS(E32<18,"0-17",E32<35,"18-34",E32<50,"35-49",E32<65,"50-64",TRUE,"65+")} -> 50-64 | G32: =enrollment!M32 -> F | H32: =enrollment!N32 -> 1.4 | I32: =enrollment!O32 -> 2233445566 | J32: =IFERROR(_xlfn.XLOOKUP(I32,providers!$B$2:$B$11,providers!$Q$2:$Q$11),"") -> 3.5 | K32: =SUMIFS(member_months!$F:$F,member_months!$A:$A,$A32) -> 12 | L32: =SUMIFS(claims!$Q:$Q,claims!$B:$B,$A32) -> 2391.46 | M32: =IF(K32=0,0,L32/K32) -> 199.28833 | N32: =SUMIFS(claims!$Q:$Q,claims!$B:$B,$A32,claims!$Z:$Z,"Inpatient") -> 0 | O32: =SUMIFS(claims!$Q:$Q,claims!$B:$B,$A32,claims!$Z:$Z,"ED") -> 1782.4 | P32: =SUMIFS(claims!$Q:$Q,claims!$B:$B,$A32,claims!$Z:$Z,"Specialty Rx") -> 0 | Q32: =IF($L32>=$U$2,1,0) -> 0 | AA32: =COUNTIFS(claims!$B:$B,$A32,claims!$Z:$Z,"Behavioral Health") -> 0 | AB32: =COUNTIFS(claims!$B:$B,$A32,claims!$Z:$Z,"ED") -> 2 | AC32: =COUNTIFS(claims!$B:$B,$A32,claims!$Z:$Z,"Inpatient") -> 0 | AD32: =IF(AA32>0,1,0) -> 0 | AE32: =IF(enrollment!P32="","",enrollment!P32) | AF32: =IF(enrollment!P32="",0,1) -> 0
A33: =enrollment!A33 -> M-000032 | B33: =enrollment!F33 -> Commercial | C33: =enrollment!I33 -> OH | D33: =enrollment!J33 -> Cuyahoga | E33: =enrollment!L33 -> 79 | F33: {=_xlfn.IFS(E33<18,"0-17",E33<35,"18-34",E33<50,"35-49",E33<65,"50-64",TRUE,"65+")} -> 65+ | G33: =enrollment!M33 -> F | H33: =enrollment!N33 -> 2.1 | I33: =enrollment!O33 -> 2345678901 | J33: =IFERROR(_xlfn.XLOOKUP(I33,providers!$B$2:$B$11,providers!$Q$2:$Q$11),"") -> 4.2 | K33: =SUMIFS(member_months!$F:$F,member_months!$A:$A,$A33) -> 12 | L33: =SUMIFS(claims!$Q:$Q,claims!$B:$B,$A33) -> 28865.21 | M33: =IF(K33=0,0,L33/K33) -> 2405.4342 | N33: =SUMIFS(claims!$Q:$Q,claims!$B:$B,$A33,claims!$Z:$Z,"Inpatient") -> 27155.48 | O33: =SUMIFS(claims!$Q:$Q,claims!$B:$B,$A33,claims!$Z:$Z,"ED") -> 0 | P33: =SUMIFS(claims!$Q:$Q,claims!$B:$B,$A33,claims!$Z:$Z,"Specialty Rx") -> 840.18 | Q33: =IF($L33>=$U$2,1,0) -> 0 | AA33: =COUNTIFS(claims!$B:$B,$A33,claims!$Z:$Z,"Behavioral Health") -> 1 | AB33: =COUNTIFS(claims!$B:$B,$A33,claims!$Z:$Z,"ED") -> 0 | AC33: =COUNTIFS(claims!$B:$B,$A33,claims!$Z:$Z,"Inpatient") -> 2 | AD33: =IF(AA33>0,1,0) -> 1 | AE33: =IF(enrollment!P33="","",enrollment!P33) | AF33: =IF(enrollment!P33="",0,1) -> 0
A34: =enrollment!A34 -> M-000033 | B34: =enrollment!F34 -> Commercial | C34: =enrollment!I34 -> TN | D34: =enrollment!J34 -> Davidson | E34: =enrollment!L34 -> 75 | F34: {=_xlfn.IFS(E34<18,"0-17",E34<35,"18-34",E34<50,"35-49",E34<65,"50-64",TRUE,"65+")} -> 65+ | G34: =enrollment!M34 -> F | H34: =enrollment!N34 -> 2.66 | I34: =enrollment!O34 -> 7890123456 | J34: =IFERROR(_xlfn.XLOOKUP(I34,providers!$B$2:$B$11,providers!$Q$2:$Q$11),"") -> 3.9 | K34: =SUMIFS(member_months!$F:$F,member_months!$A:$A,$A34) -> 12 | L34: =SUMIFS(claims!$Q:$Q,claims!$B:$B,$A34) -> 23139.01 | M34: =IF(K34=0,0,L34/K34) -> 1928.2508 | N34: =SUMIFS(claims!$Q:$Q,claims!$B:$B,$A34,claims!$Z:$Z,"Inpatient") -> 20664.86 | O34: =SUMIFS(claims!$Q:$Q,claims!$B:$B,$A34,claims!$Z:$Z,"ED") -> 2135.9 | P34: =SUMIFS(claims!$Q:$Q,claims!$B:$B,$A34,claims!$Z:$Z,"Specialty Rx") -> 0 | Q34: =IF($L34>=$U$2,1,0) -> 0 | AA34: =COUNTIFS(claims!$B:$B,$A34,claims!$Z:$Z,"Behavioral Health") -> 1 | AB34: =COUNTIFS(claims!$B:$B,$A34,claims!$Z:$Z,"ED") -> 2 | AC34: =COUNTIFS(claims!$B:$B,$A34,claims!$Z:$Z,"Inpatient") -> 1 | AD34: =IF(AA34>0,1,0) -> 1 | AE34: =IF(enrollment!P34="","",enrollment!P34) | AF34: =IF(enrollment!P34="",0,1) -> 0
